Workbook
Name Segment_Canal_acces: #N/A
Name Segment_Phase_parcours: #N/A
Name Segment_Secteur: #N/A
Name Segment_Ville: #N/A

Sheet Grille d’audit 
B2: Score accessibilité
B3: Critère | C3: /20
B4: Rampe accès | C4: 20
B5: Signalétique claire | C5: 20
B6: Accessibilité numérique | C6: 20
B7: Accueil adapté | C7: 20
B8: Clarté information | C8: 20
B9: Total | C9: 100
B15: Temps d’attente
B17: Collecte possible
B18: Système de ticketing
B19: Borne numérique
B20: Estimation automatique (badge entrée / sortie)
B25: Satisfaction (1 à 5)
B27: Collecte possible
B28: Borne smiley en sortie
B29: Questionnaire QR code
B30: Mini sondage email
B34: Catégorie de problème
B36: Collecte possible
C37: Liste fermée obligatoire
B38: Sélection par l’agent Formulaire post-visite : À quelle heure avez-vous attendu avant d'être reçu ? (minutes) Êtes-vous satisfait ? (1-5 étoiles) Quel était le problème principal ? (liste déroulante) Gravité du problème ? (Mineur/Moyen/Grave) Avez-vous pu accéder facilement ? (score 0-100 ou Facile/Moyen/Difficile) | C38: Accueil Attente Signalétique Numérique Information Accéssibilité physique Bruit
B42: Gravité (1 à 3)
B44: Évaluée par
C45: Liste fermée obligatoire
B46: Responsable de site Superviseur Système de classification interne | C46: 1 = mineur 2 = modéré 3 = critique

Sheet Méthodologie
I2: Méthodologie

Sheet Paramètres
I1: Secteur | J1: Type_lieu | K1: Insatisfait
B2: Paramètres | I2: Service | J2: Centre social | K2: 1
B3: Paramètre | C3: Valeur | I3: Éducation | J3: École | K3: 1
B4: Seuil insatisfaction (<=) | C4: 2 | I4: Éducation | J4: École | K4: 1
B5: Seuil mauvais accès (<) | C5: 60 | I5: Culture | J5: Bibliothèque | K5: 1
B6: Seuil attente longue (>) | C6: 30 | I6: Éducation | J6: Médiathèque | K6: 1
I7: Éducation | J7: Centre de formation | K7: 1
B8: Nb Observations | C8: 250 | I8: Éducation | J8: Médiathèque | K8: 1
B11: Définition | I11: Éducation | J11: Centre de formation | K11: 1
B12: Insatisfait = | C12: satisfaction ≤ seuil | I12: Service | J12: Mairie | K12: 1
B13: Mauvais accès = | C13: score < seuil | I13: Culture | J13: Bibliothèque | K13: 1
B14: Attente longue = | C14: attente > seuil | I14: Éducation | J14: Centre de formation | K14: 1
B15: Corrélation forte → | C15: 0,6 ou plus | I15: Éducation | J15: École | K15: 1
B16: Corrélation modérée → | C16: 0.3 | I16: Éducation | J16: École | K16: 1
B17: Corrélation faible → | C17: 0
I18: Culture | J18: Salle d’exposition | K18: 1
I19: Service | J19: Centre social | K19: 1
B20: Taux d'insatisfaction | C20: =Insatisfaction[[#Totals],[Insatisfait]]/$C$8 -> 0.228 | I20: Éducation | J20: Médiathèque | K20: 1
I21: Service | J21: Centre social | K21: 1
I22: Éducation | J22: Centre de formation | K22: 1
I23: Éducation | J23: Centre de formation | K23: 1
I24: Service | J24: Centre social | K24: 1
I25: Éducation | J25: Centre de formation | K25: 1
I26: Service | J26: Centre social | K26: 1
I27: Éducation | J27: Médiathèque | K27: 1
I28: Culture | J28: Salle d’exposition | K28: 1
I29: Éducation | J29: École | K29: 1
I30: Éducation | J30: École | K30: 1
I31: Culture | J31: Salle d’exposition | K31: 1
I32: Éducation | J32: Centre de formation | K32: 1
... I61: Service | J61: CAF locale | K61: 1
I62: Total | K62: =SUBTOTAL(109,Insatisfaction[Insatisfait]) -> 57

Sheet Data
A1: Date_observation | B1: Ville | C1: code_postal | D1: Secteur | E1: Type_lieu | F1: Temps_attente_minutes | G1: Niveau_satisfaction_1_5 | H1: Categorie_problème | I1: Niveau_gravite_1_3 | J1: Score_accessibilite_0_100 | K1: Phase_parcours | L1: Canal_acces
A2: 45707 | B2: Grenoble | C2: 38400 | D2: Éducation | E2: Centre de formation | F2: 32 | G2: 3 | H2: Attente | I2: 2 | J2: 54 | K2: Accueil & Orientation | L2: Borne
A3: 45698 | B3: Lyon | C3: 69003 | D3: Service | E3: Centre social | F3: 32 | G3: 3 | H3: Info | I3: 2 | J3: 64 | K3: Diagnostic / Évaluation | L3: Borne
A4: 45733 | B4: Lyon | C4: 69002 | D4: Culture | E4: Musée | F4: 24 | G4: 4 | H4: Bruit | I4: 3 | J4: 52 | K4: Orientation | L4: Borne
A5: 45721 | B5: Grenoble | C5: 38100 | D5: Service | E5: Maison des services | F5: 26 | G5: 3 | H5: Attente | I5: 3 | J5: 76 | K5: Paiement | L5: Borne
A6: 45664 | B6: Grenoble | C6: 38100 | D6: Éducation | E6: Centre de formation | F6: 4 | G6: 5 | H6: Numérique | I6: 3 | J6: 80 | K6: Diagnostic / Évaluation | L6: En ligne
A7: 45740 | B7: Villeurbanne | C7: 69100 | D7: Éducation | E7: École primaire | F7: 25 | G7: 3 | H7: Accueil | I7: 2 | J7: 84 | K7: Paiement | L7: Téléphone
A8: 45715 | B8: Valence | C8: 26000 | D8: Culture | E8: Musée | F8: 29 | G8: 3 | H8: Accessibilité physique | I8: 2 | J8: 90 | K8: Orientation | L8: Borne
A9: 45707 | B9: Villeurbanne | C9: 69100 | D9: Service | E9: Centre social | F9: 27 | G9: 2 | H9: Numérique | I9: 1 | J9: 94 | K9: Traitement dossier | L9: Téléphone
A10: 45684 | B10: Grenoble | C10: 38400 | D10: Service | E10: Centre social | F10: 4 | G10: 5 | H10: Accueil | I10: 2 | J10: 70 | K10: Traitement dossier | L10: En ligne
A11: 45716 | B11: Annecy | C11: 74000 | D11: Éducation | E11: Médiathèque | F11: 25 | G11: 3 | H11: Attente | I11: 1 | J11: 54 | K11: Orientation | L11: Sur place
A12: 45658 | B12: Lyon | C12: 69003 | D12: Service | E12: Maison des services | F12: 6 | G12: 4 | H12: Accueil | I12: 3 | J12: 84 | K12: Accueil & Orientation | L12: Sur place
A13: 45712 | B13: Villeurbanne | C13: 69100 | D13: Service | E13: Mairie | F13: 24 | G13: 3 | H13: Numérique | I13: 2 | J13: 77 | K13: Orientation | L13: Borne
... A251: 45710 | B251: Saint-Étienne | C251: 42000 | D251: Service | E251: Agence administrative | F251: 16 | G251: 4 | H251: Numérique | I251: 1 | J251: 80 | K251: Paiement | L251: Borne

Sheet Data_Model
A1: Date_observation | B1: Ville | C1: code_postal | D1: Secteur | E1: Type_lieu | F1: Temps_attente_minutes | G1: Niveau_satisfaction_1_5 | H1: Catégorie_problème | I1: Niveau_gravité_1_3 | J1: Score_accessibilité_0_100 | K1: Phase_parcours | L1: Canal_acces | M1: Insatisfait | N1: Gravité critique | O1: Mauvais accès | P1: Attente longue
A2: 45707 | B2: Grenoble | C2: 38400 | D2: Éducation | E2: Centre de formation | F2: 32 | G2: 3 | H2: Attente | I2: 2 | J2: 54 | K2: Accueil & Orientation | L2: Borne | M2: =IF(DataKPI[[#This Row],[Niveau_satisfaction_1_5]]<=Paramètres!$C$4,1,0) -> 0 | N2: =IF(DataKPI[[#This Row],[Niveau_gravité_1_3]]=3,1,0) -> 0 | O2: =IF(DataKPI[[#This Row],[Score_accessibilité_0_100]]<Paramètres!$C$5,1,0) -> 1 | P2: =IF(DataKPI[[#This Row],[Temps_attente_minutes]]>Paramètres!$C$6,1,0) -> 1
A3: 45698 | B3: Lyon | C3: 69003 | D3: Service | E3: Centre social | F3: 32 | G3: 3 | H3: Info | I3: 2 | J3: 64 | K3: Diagnostic / Évaluation | L3: Borne | M3: =IF(DataKPI[[#This Row],[Niveau_satisfaction_1_5]]<=Paramètres!$C$4,1,0) -> 0 | N3: =IF(DataKPI[[#This Row],[Niveau_gravité_1_3]]=3,1,0) -> 0 | O3: =IF(DataKPI[[#This Row],[Score_accessibilité_0_100]]<Paramètres!$C$5,1,0) -> 0 | P3: =IF(DataKPI[[#This Row],[Temps_attente_minutes]]>Paramètres!$C$6,1,0) -> 1
A4: 45733 | B4: Lyon | C4: 69002 | D4: Culture | E4: Musée | F4: 24 | G4: 4 | H4: Bruit | I4: 3 | J4: 52 | K4: Orientation | L4: Borne | M4: =IF(DataKPI[[#This Row],[Niveau_satisfaction_1_5]]<=Paramètres!$C$4,1,0) -> 0 | N4: =IF(DataKPI[[#This Row],[Niveau_gravité_1_3]]=3,1,0) -> 1 | O4: =IF(DataKPI[[#This Row],[Score_accessibilité_0_100]]<Paramètres!$C$5,1,0) -> 1 | P4: =IF(DataKPI[[#This Row],[Temps_attente_minutes]]>Paramètres!$C$6,1,0) -> 0
A5: 45721 | B5: Grenoble | C5: 38100 | D5: Service | E5: Maison des services | F5: 26 | G5: 3 | H5: Attente | I5: 3 | J5: 76 | K5: Paiement | L5: Borne | M5: =IF(DataKPI[[#This Row],[Niveau_satisfaction_1_5]]<=Paramètres!$C$4,1,0) -> 0 | N5: =IF(DataKPI[[#This Row],[Niveau_gravité_1_3]]=3,1,0) -> 1 | O5: =IF(DataKPI[[#This Row],[Score_accessibilité_0_100]]<Paramètres!$C$5,1,0) -> 0 | P5: =IF(DataKPI[[#This Row],[Temps_attente_minutes]]>Paramètres!$C$6,1,0) -> 0
A6: 45664 | B6: Grenoble | C6: 38100 | D6: Éducation | E6: Centre de formation | F6: 4 | G6: 5 | H6: Numérique | I6: 3 | J6: 80 | K6: Diagnostic / Évaluation | L6: En ligne | M6: =IF(DataKPI[[#This Row],[Niveau_satisfaction_1_5]]<=Paramètres!$C$4,1,0) -> 0 | N6: =IF(DataKPI[[#This Row],[Niveau_gravité_1_3]]=3,1,0) -> 1 | O6: =IF(DataKPI[[#This Row],[Score_accessibilité_0_100]]<Paramètres!$C$5,1,0) -> 0 | P6: =IF(DataKPI[[#This Row],[Temps_attente_minutes]]>Paramètres!$C$6,1,0) -> 0
A7: 45740 | B7: Villeurbanne | C7: 69100 | D7: Éducation | E7: École primaire | F7: 25 | G7: 3 | H7: Accueil | I7: 2 | J7: 84 | K7: Paiement | L7: Téléphone | M7: =IF(DataKPI[[#This Row],[Niveau_satisfaction_1_5]]<=Paramètres!$C$4,1,0) -> 0 | N7: =IF(DataKPI[[#This Row],[Niveau_gravité_1_3]]=3,1,0) -> 0 | O7: =IF(DataKPI[[#This Row],[Score_accessibilité_0_100]]<Paramètres!$C$5,1,0) -> 0 | P7: =IF(DataKPI[[#This Row],[Temps_attente_minutes]]>Paramètres!$C$6,1,0) -> 0
A8: 45715 | B8: Valence | C8: 26000 | D8: Culture | E8: Musée | F8: 29 | G8: 3 | H8: Accessibilité physique | I8: 2 | J8: 90 | K8: Orientation | L8: Borne | M8: =IF(DataKPI[[#This Row],[Niveau_satisfaction_1_5]]<=Paramètres!$C$4,1,0) -> 0 | N8: =IF(DataKPI[[#This Row],[Niveau_gravité_1_3]]=3,1,0) -> 0 | O8: =IF(DataKPI[[#This Row],[Score_accessibilité_0_100]]<Paramètres!$C$5,1,0) -> 0 | P8: =IF(DataKPI[[#This Row],[Temps_attente_minutes]]>Paramètres!$C$6,1,0) -> 0
A9: 45707 | B9: Villeurbanne | C9: 69100 | D9: Service | E9: Centre social | F9: 27 | G9: 2 | H9: Numérique | I9: 1 | J9: 94 | K9: Traitement dossier | L9: Téléphone | M9: =IF(DataKPI[[#This Row],[Niveau_satisfaction_1_5]]<=Paramètres!$C$4,1,0) -> 1 | N9: =IF(DataKPI[[#This Row],[Niveau_gravité_1_3]]=3,1,0) -> 0 | O9: =IF(DataKPI[[#This Row],[Score_accessibilité_0_100]]<Paramètres!$C$5,1,0) -> 0 | P9: =IF(DataKPI[[#This Row],[Temps_attente_minutes]]>Paramètres!$C$6,1,0) -> 0
A10: 45684 | B10: Grenoble | C10: 38400 | D10: Service | E10: Centre social | F10: 4 | G10: 5 | H10: Accueil | I10: 2 | J10: 70 | K10: Traitement dossier | L10: En ligne | M10: =IF(DataKPI[[#This Row],[Niveau_satisfaction_1_5]]<=Paramètres!$C$4,1,0) -> 0 | N10: =IF(DataKPI[[#This Row],[Niveau_gravité_1_3]]=3,1,0) -> 0 | O10: =IF(DataKPI[[#This Row],[Score_accessibilité_0_100]]<Paramètres!$C$5,1,0) -> 0 | P10: =IF(DataKPI[[#This Row],[Temps_attente_minutes]]>Paramètres!$C$6,1,0) -> 0
A11: 45716 | B11: Annecy | C11: 74000 | D11: Éducation | E11: Médiathèque | F11: 25 | G11: 3 | H11: Attente | I11: 1 | J11: 54 | K11: Orientation | L11: Sur place | M11: =IF(DataKPI[[#This Row],[Niveau_satisfaction_1_5]]<=Paramètres!$C$4,1,0) -> 0 | N11: =IF(DataKPI[[#This Row],[Niveau_gravité_1_3]]=3,1,0) -> 0 | O11: =IF(DataKPI[[#This Row],[Score_accessibilité_0_100]]<Paramètres!$C$5,1,0) -> 1 | P11: =IF(DataKPI[[#This Row],[Temps_attente_minutes]]>Paramètres!$C$6,1,0) -> 0
A12: 45658 | B12: Lyon | C12: 69003 | D12: Service | E12: Maison des services | F12: 6 | G12: 4 | H12: Accueil | I12: 3 | J12: 84 | K12: Accueil & Orientation | L12: Sur place | M12: =IF(DataKPI[[#This Row],[Niveau_satisfaction_1_5]]<=Paramètres!$C$4,1,0) -> 0 | N12: =IF(DataKPI[[#This Row],[Niveau_gravité_1_3]]=3,1,0) -> 1 | O12: =IF(DataKPI[[#This Row],[Score_accessibilité_0_100]]<Paramètres!$C$5,1,0) -> 0 | P12: =IF(DataKPI[[#This Row],[Temps_attente_minutes]]>Paramètres!$C$6,1,0) -> 0
A13: 45712 | B13: Villeurbanne | C13: 69100 | D13: Service | E13: Mairie | F13: 24 | G13: 3 | H13: Numérique | I13: 2 | J13: 77 | K13: Orientation | L13: Borne | M13: =IF(DataKPI[[#This Row],[Niveau_satisfaction_1_5]]<=Paramètres!$C$4,1,0) -> 0 | N13: =IF(DataKPI[[#This Row],[Niveau_gravité_1_3]]=3,1,0) -> 0 | O13: =IF(DataKPI[[#This Row],[Score_accessibilité_0_100]]<Paramètres!$C$5,1,0) -> 0 | P13: =IF(DataKPI[[#This Row],[Temps_attente_minutes]]>Paramètres!$C$6,1,0) -> 0
... A251: 45710 | B251: Saint-Étienne | C251: 42000 | D251: Service | E251: Agence administrative | F251: 16 | G251: 4 | H251: Numérique | I251: 1 | J251: 80 | K251: Paiement | L251: Borne | M251: =IF(DataKPI[[#This Row],[Niveau_satisfaction_1_5]]<=Paramètres!$C$4,1,0) -> 0 | N251: =IF(DataKPI[[#This Row],[Niveau_gravité_1_3]]=3,1,0) -> 0 | O251: =IF(DataKPI[[#This Row],[Score_accessibilité_0_100]]<Paramètres!$C$5,1,0) -> 0 | P251: =IF(DataKPI[[#This Row],[Temps_attente_minutes]]>Paramètres!$C$6,1,0) -> 0

Sheet Détails1
A1: Détails pou for Temps d'attente moyen - Mois (Date_observation): Feb, Attente longue: 1
A3: Date_observation | B3: Ville | C3: code_postal | D3: Secteur | E3: Type_lieu | F3: Temps_attente_minutes | G3: Niveau_satisfaction_1_5 | H3: Catégorie_problème | I3: Niveau_gravite_1_3 | J3: Score_accessibilite_0_100 | K3: Phase_parcours | L3: Canal_acces | M3: Insatisfait | N3: Gravité critique | O3: Mauvais accès | P3: Attente longue
A4: 45689 | B4: Villeurbanne | C4: 69100 | D4: Éducation | E4: École primaire | F4: 35 | G4: 2 | H4: Numérique | I4: 1 | J4: 55 | K4: Paiement | L4: Sur place | M4: 1 | N4: 0 | O4: 1 | P4: 1
A5: 45690 | B5: Saint-Étienne | C5: 42800 | D5: Service | E5: Mairie | F5: 40 | G5: 3 | H5: Numérique | I5: 1 | J5: 70 | K5: Traitement dossier | L5: En ligne | M5: 0 | N5: 0 | O5: 0 | P5: 1
A6: 45691 | B6: Valence | C6: 26000 | D6: Culture | E6: Salle d’exposition | F6: 34 | G6: 3 | H6: Numérique | I6: 3 | J6: 65 | K6: Diagnostic / Évaluation | L6: Borne | M6: 0 | N6: 1 | O6: 0 | P6: 1
A7: 45694 | B7: Saint-Étienne | C7: 42100 | D7: Service | E7: Centre social | F7: 35 | G7: 4 | H7: Bruit | I7: 1 | J7: 72 | K7: Orientation | L7: Borne | M7: 0 | N7: 0 | O7: 0 | P7: 1
A8: 45695 | B8: Annecy | C8: 74000 | D8: Éducation | E8: Centre de formation | F8: 31 | G8: 2 | H8: Attente | I8: 2 | J8: 76 | K8: Traitement dossier | L8: Borne | M8: 1 | N8: 0 | O8: 0 | P8: 1
A9: 45695 | B9: Lyon | C9: 69001 | D9: Culture | E9: Bibliothèque | F9: 35 | G9: 3 | H9: Numérique | I9: 1 | J9: 76 | K9: Traitement dossier | L9: Téléphone | M9: 0 | N9: 0 | O9: 0 | P9: 1
A10: 45695 | B10: Grenoble | C10: 38400 | D10: Éducation | E10: Centre de formation | F10: 40 | G10: 2 | H10: Accueil | I10: 2 | J10: 81 | K10: Diagnostic / Évaluation | L10: En ligne | M10: 1 | N10: 0 | O10: 0 | P10: 1
A11: 45698 | B11: Lyon | C11: 69003 | D11: Service | E11: Centre social | F11: 32 | G11: 3 | H11: Info | I11: 2 | J11: 64 | K11: Diagnostic / Évaluation | L11: Borne | M11: 0 | N11: 0 | O11: 0 | P11: 1
A12: 45699 | B12: Saint-Étienne | C12: 42800 | D12: Service | E12: Mairie | F12: 35 | G12: 2 | H12: Numérique | I12: 1 | J12: 56 | K12: Traitement dossier | L12: Borne | M12: 1 | N12: 0 | O12: 1 | P12: 1
A13: 45699 | B13: Lyon | C13: 69007 | D13: Éducation | E13: Centre de formation | F13: 34 | G13: 2 | H13: Signalétique | I13: 2 | J13: 91 | K13: Orientation | L13: Sur place | M13: 1 | N13: 0 | O13: 0 | P13: 1
A14: 45699 | B14: Lyon | C14: 69007 | D14: Service | E14: Centre social | F14: 38 | G14: 1 | H14: Info | I14: 1 | J14: 54 | K14: Orientation | L14: Borne | M14: 1 | N14: 0 | O14: 1 | P14: 1
A15: 45700 | B15: Villeurbanne | C15: 69100 | D15: Éducation | E15: Centre de formation | F15: 32 | G15: 5 | H15: Accessibilité physique | I15: 1 | J15: 63 | K15: Accueil & Orientation | L15: Borne | M15: 0 | N15: 0 | O15: 0 | P15: 1
... A24: 45716 | B24: Lyon | C24: 69007 | D24: Culture | E24: Musée | F24: 34 | G24: 4 | H24: Accueil | I24: 1 | J24: 66 | K24: Orientation | L24: Sur place | M24: 0 | N24: 0 | O24: 0 | P24: 1

Sheet TCD
A11: Satisfaction moyenne | B11: Temps moyen_attente | C11: Moyenne des mauvais accès | D11: Gravité critique moyenne | E11: Attente longue moyenne | F11: Moyenne_Insatisfait | G11: Score moyen_accessibilité | H11: Nombre observations
A12: 3.476 | B12: 20.484 | C12: 0.168 | D12: 0.38 | E12: 0.224 | F12: 0.228 | G12: 74.516 | H12: 250
B18: Performance opérationnelle
A22: Temps d'attente moyen par ville
B24: Ville | C24: Temps d'attente moyen
B25: Grenoble | C25: 21.837838
B26: Valence | C26: 21.075
B27: Lyon | C27: 20.875
B28: Saint-Étienne | C28: 20.42
B29: Annecy | C29: 20.4
B30: Villeurbanne | C30: 18.315789
A34: Moyenne de temps d'attente par mois
B38: Moyenne_Insatisfait | C38: Attente longue
B39: Mois | C39: 0 | D39: 1
B40: janv | C40: 0.15254237 | D40: 0.47058824
B41: févr | C41: 0.14545455 | D41: 0.42857143
B42: mars | C42: 0.21538462 | D42: 0.46666667
B43: avr | C43: 0 | D43: 0.66666667
B44: mai | C44: 0
A46: Temps d'attente moyen par phase de parcours
B48: Phase de parcours | C48: Temps d'attente moyen
B49: Traitement dossier | C49: 21.267857
B50: Accueil & Orientation | C50: 21.159091
B51: Information | C51: 21.111111
B52: Orientation | C52: 20.770833
B53: Diagnostic / Évaluation | C53: 19.603774
B54: Paiement | C54: 19.325
A58: Score moyen par canal
B60: Canal | C60: Score moyen_accessibilité
B61: Borne | C61: 72.970588
B62: En ligne | C62: 74.786885
B63: Sur place | C63: 73.383333
B64: Téléphone | C64: 77.081967
B71: Satisfaction usagers
A74: Satisfaction moyenne par ville
B76: Ville | C76: Satisfaction moyenne
B77: Saint-Étienne | C77: 4.12
B78: Annecy | C78: 3.6222222
B79: Villeurbanne | C79: 3.3947368
B80: Lyon | C80: 3.275
...

Sheet Dasboard
E3: Dasboaord DATA
A10: Résumé KPI
A12: Indicateur | B12: Valeur
A13: Nombre d'observations | B13: =GETPIVOTDATA("Nombre observations",TCD!$A$11) -> 250
A14: Score accessibilité moyen | B14: =GETPIVOTDATA("Score moyen_accessibilité",TCD!$A$11) -> 74.516
A15: Satisfaction moyenne | B15: =GETPIVOTDATA("Satisfaction moyenne",TCD!$A$11) -> 3.476
A16: % insatisfaction global | B16: =GETPIVOTDATA("Moyenne_Insatisfait",TCD!$A$11) -> 0.228
A17: % Gravité critique | B17: =GETPIVOTDATA("Gravité critique moyenne",TCD!$A$11) -> 0.38
A18: Mauvais accès | B18: =GETPIVOTDATA("Moyenne des mauvais accès",TCD!$A$11) -> 0.168
A19: Temps d'attente moyen global | B19: =GETPIVOTDATA("Temps moyen_attente",TCD!$A$11) -> 20.484
A20: Correlation Attente/Insatisfaction | B20: =CORREL(DataKPI[Temps_attente_minutes],DataKPI[Insatisfait]) -> 0.27155259 | C20: =Paramètres!$B$16 -> Corrélation modérée →
B28: Segments intéractifs
B56: Performance territoriale
B114: Expérience usager
B172: Diagnostic
A280: Données simulées à des fins pédagogiques – 250 observations – Analyse statistique et outil d’aide à la décision.

Sheet Analyse
K4: Analyse
I7: ÉTUDE 1 : Attente longue (0 vs 1)
C10: Le dépassement du seuil de 30 minutes augmente-t-il significativement le taux d’insatisfaction ?
A15: 1. Quelle est la différence de taux ?
B16: Attente longue
B17: 0 | C17: 1
A18: Taux_Insatisfait | B18: 0.15979381 | C18: 0.46428571
A31: 2. Est-elle stable selon les villes ?
A32: Taux_Insatisfait | B32: Attente longue
A33: Ville | B33: 0 | C33: 1
A34: Villeurbanne | B34: 0.24242424 | C34: 0.6
A35: Saint-Étienne | B35: 0 | C35: 0.55555556
A36: Grenoble | B36: 0.19230769 | C36: 0.54545455
A37: Lyon | B37: 0.14285714 | C37: 0.5
A38: Annecy | B38: 0.090909091 | C38: 0.41666667
A39: Valence | B39: 0.33333333 | C39: 0.14285714
A53: 3. Est-elle amplifiée selon le canal ?
A54: Taux_Insatisfait | B54: Attente longue
A55: Canal | B55: 0 | C55: 1
A56: Sur place | B56: 0.093023256 | C56: 0.58823529
A57: Borne | B57: 0.10204082 | C57: 0.52631579
A58: En ligne | B58: 0.24 | C58: 0.45454545
A59: Téléphone | B59: 0.19230769 | C59: 0.11111111
I77: ÉTUDE 2 : Corrélation attente longue / insatisfaction
C79: Plus le temps d’attente moyen est élevé, plus l’insatisfaction augmente-t-elle ?
A81: Étude 2A — Relation linéaire
B82: Attente longue
B83: 0 | D83: 1
A84: Ville | B84: Temps d'attente moyen | C84: Taux_Insatisfait | D84: Temps d'attente moyen | E84: Taux_Insatisfait
A85: Annecy | B85: 15.30303 | C85: 0.090909091 | D85: 34.416667 | E85: 0.41666667
A86: Grenoble | B86: 16.076923 | C86: 0.19230769 | D86: 35.454545 | E86: 0.54545455
A87: Lyon | B87: 14.321429 | C87: 0.14285714 | D87: 36.166667 | E87: 0.5
A88: Saint-Étienne | B88: 17.170732 | C88: 0 | D88: 35.222222 | E88: 0.55555556
A89: Valence | B89: 18.181818 | C89: 0.33333333 | D89: 34.714286 | E89: 0.14285714
A90: Villeurbanne | B90: 15.909091 | C90: 0.24242424 | D90: 34.2 | E90: 0.6
A93: Temps d'attente moyen | B93: Taux_Insatisfait
A94: 34.416667 | B94: 0.41666667
A95: 35.454545 | B95: 0.54545455
A96: 36.166667 | B96: 0.5
A97: 35.222222 | B97: 0.55555556
...
